<?xml version="1.0"?>
<mujoco model="xmls/linear_actuator_array-v0.xml">
  <default>
    <joint limited='true' />
  </default>
  <worldbody>
    <light name="light0" directional="true" diffuse=".3 .3 .3" pos="-1 -1 1" dir="1 1 -1" />
    <light name="light1" directional="true" diffuse=".3 .3 .3" pos="1 -1 1" dir="-1 1 -1" />
    <light name="light2" directional="true" diffuse=".3 .3 .3" pos="0 1 1" dir="0 -1 -1" />
    <body name="object0" pos="0.0 0.0 4.15">
      <freejoint name="object0_joint" />
      <geom name="object0_geom" type="sphere" size="0.1" />
    </body>
    <geom name="floor" pos="0 0 0" size="5.0 5.0 .1" type="plane" condim="3" />
    <body name="palm" pos="0 0 4.0">
      <body name="module0" pos="-0.18 -0.12 0">
        <geom name="module0_geom" type="box" size="0.05" fromto="0 0 0 0 0 -0.4" />
        <joint name="module0_joint" type="slide" pos="0 0 0" axis="0 0 1" range="-0.01 0"
        damping="10000" />
      </body>
      <body name="module1" pos="-0.18 0.0 0">
        <geom name="module1_geom" type="box" size="0.05" fromto="0 0 0 0 0 -0.4" />
        <joint name="module1_joint" type="slide" pos="0 0 0" axis="0 0 1" range="-0.01 0"
        damping="10000" />
      </body>
      <body name="module2" pos="-0.18 0.12 0">
        <geom name="module2_geom" type="box" size="0.05" fromto="0 0 0 0 0 -0.4" />
        <joint name="module2_joint" type="slide" pos="0 0 0" axis="0 0 1" range="-0.01 0"
        damping="10000" />
      </body>
      <body name="module3" pos="-0.06 -0.12 0">
        <geom name="module3_geom" type="box" size="0.05" fromto="0 0 0 0 0 -0.4" />
        <joint name="module3_joint" type="slide" pos="0 0 0" axis="0 0 1" range="-0.01 0"
        damping="10000" />
      </body>
      <body name="module4" pos="-0.06 0.0 0">
        <geom name="module4_geom" type="box" size="0.05" fromto="0 0 0 0 0 -0.4" />
        <joint name="module4_joint" type="slide" pos="0 0 0" axis="0 0 1" range="-0.01 0"
        damping="10000" />
      </body>
      <body name="module5" pos="-0.06 0.12 0">
        <geom name="module5_geom" type="box" size="0.05" fromto="0 0 0 0 0 -0.4" />
        <joint name="module5_joint" type="slide" pos="0 0 0" axis="0 0 1" range="-0.01 0"
        damping="10000" />
      </body>
      <body name="module6" pos="0.06 -0.12 0">
        <geom name="module6_geom" type="box" size="0.05" fromto="0 0 0 0 0 -0.4" />
        <joint name="module6_joint" type="slide" pos="0 0 0" axis="0 0 1" range="-0.01 0"
        damping="10000" />
      </body>
      <body name="module7" pos="0.06 0.0 0">
        <geom name="module7_geom" type="box" size="0.05" fromto="0 0 0 0 0 -0.4" />
        <joint name="module7_joint" type="slide" pos="0 0 0" axis="0 0 1" range="-0.01 0"
        damping="10000" />
      </body>
      <body name="module8" pos="0.06 0.12 0">
        <geom name="module8_geom" type="box" size="0.05" fromto="0 0 0 0 0 -0.4" />
        <joint name="module8_joint" type="slide" pos="0 0 0" axis="0 0 1" range="-0.01 0"
        damping="10000" />
      </body>
      <body name="module9" pos="0.18 -0.12 0">
        <geom name="module9_geom" type="box" size="0.05" fromto="0 0 0 0 0 -0.4" />
        <joint name="module9_joint" type="slide" pos="0 0 0" axis="0 0 1" range="-0.01 0"
        damping="10000" />
      </body>
      <body name="module10" pos="0.18 0.0 0">
        <geom name="module10_geom" type="box" size="0.05" fromto="0 0 0 0 0 -0.4" />
        <joint name="module10_joint" type="slide" pos="0 0 0" axis="0 0 1" range="-0.01 0"
        damping="10000" />
      </body>
      <body name="module11" pos="0.18 0.12 0">
        <geom name="module11_geom" type="box" size="0.05" fromto="0 0 0 0 0 -0.4" />
        <joint name="module11_joint" type="slide" pos="0 0 0" axis="0 0 1" range="-0.01 0"
        damping="10000" />
      </body>
    </body>
  </worldbody>
  <actuator>
    <motor name="motor0" gear="20000" joint="module0_joint" />
    <motor name="motor1" gear="20000" joint="module1_joint" />
    <motor name="motor2" gear="20000" joint="module2_joint" />
    <motor name="motor3" gear="20000" joint="module3_joint" />
    <motor name="motor4" gear="20000" joint="module4_joint" />
    <motor name="motor5" gear="20000" joint="module5_joint" />
    <motor name="motor6" gear="20000" joint="module6_joint" />
    <motor name="motor7" gear="20000" joint="module7_joint" />
    <motor name="motor8" gear="20000" joint="module8_joint" />
    <motor name="motor9" gear="20000" joint="module9_joint" />
    <motor name="motor10" gear="20000" joint="module10_joint" />
    <motor name="motor11" gear="20000" joint="module11_joint" />
  </actuator>
</mujoco>
