<?xml version="1.0"?>
<mujoco model="envs/linear_actuator_array/xmls/linear_actuator_array-v0.xml">
  <worldbody>
    <light name="light0" directional="true" diffuse=".3 .3 .3" pos="-1 -1 1" dir="1 1 -1" />
    <light name="light1" directional="true" diffuse=".3 .3 .3" pos="1 -1 1" dir="-1 1 -1" />
    <light name="light2" directional="true" diffuse=".3 .3 .3" pos="0 1 1" dir="0 -1 -1" />
    <body name="object0" pos="0.0 0.0 6.5">
      <freejoint />
      <geom name="sphere0" type="sphere" size="0.1" />
    </body>
    <geom name="floor" pos="0 0 0" size="5.0 5.0 .1" type="plane" condim="3" />
    <body name="palm" pos="0 0 4.0">
      <body name="module0" pos="0.0 0.0 0">
        <geom name="box0" type="box" size="0.05 0.05 0.4" />
        <joint name="joint0" type="slide" pos="0 0 0" axis="0 0 1" range="-0.01 0"
        damping="10000" />
      </body>
    </body>
  </worldbody>
  <actuator>
    <motor name="motor0" gear="20000" joint="joint0" />
  </actuator>
</mujoco>
